<?xml version="1.0" ?>
<robot name="oyku" xmlns:xacro="http://ros.org/wiki/xacro">

  <!-- color definitions -->
  <xacro:include filename="$(find oyku_description)/urdf/common_properties.xacro"/>

  <!--

  oyku motors
 
    forward
  MFL - MFR
   |      |
   |      |
  MRL - MRR
     back

  wheel_radius_ = 0.0375
  float lx_ = 0.105; // distance between rear or front wheels divided by 2 : 10.5 cm : 0.105 m
  float ly_ = 0.0475; // distance between rear and front wheeld divided by 2 : 9.5 cm / 2 : 0.0475 m

  -->
  <xacro:property name="wheel_radius" value="0.0375" />
  <xacro:property name="wheel_width" value="0.035" />
  <xacro:property name="lx" value="0.105" />
  <xacro:property name="ly" value="0.0475" />

  <link name="base_footprint"/>

  <joint name="base_joint" type="fixed">
    <parent link="base_footprint"/>
    <child link="base_link"/>
    <origin xyz="0.0 0.0 0.010" rpy="0 0 0"/>
  </joint>

  <link name="base_link">
    <visual>
      <origin xyz="0 0 0.055" rpy="0 0 0"/>
      <geometry>
        <box size="0.155 0.2 0.075"/>
      </geometry>
      <material name="black"/>
    </visual>

    <collision>
      <origin xyz="0 0 0" rpy="0 0 0"/>
      <geometry>
        <box size="0.155 0.2 0.075"/>
      </geometry>
    </collision>

    <inertial>
      <origin xyz="0 0 0" rpy="0 0 0"/>
      <mass value="8.2573504e-01"/>
      <inertia ixx="2.2124416e-03" ixy="-1.2294101e-05" ixz="3.4938785e-05"
               iyy="2.1193702e-03" iyz="-5.0120904e-06"
               izz="2.0064271e-03" />
    </inertial>
  </link>

  <xacro:macro name="oyku_wheel" params="wheel_name x y">
    <link name="${wheel_name}">
      <visual>
        <origin xyz="0 0 0" rpy="0 0 0"/>
        <geometry>
          <cylinder length="${wheel_width}" radius="${wheel_radius}"/>
        </geometry>
        <material name="orange"/>
      </visual>

      <collision>
        <origin xyz="0 0 0" rpy="0 0 0"/>
        <geometry>
          <cylinder length="${wheel_width}" radius="${wheel_radius}"/>
        </geometry>
      </collision>

      <inertial>
        <origin xyz="0 0 0" />
        <mass value="2.8498940e-02" />
        <inertia ixx="1.1175580e-05" ixy="-4.2369783e-11" ixz="-5.9381719e-09"
                iyy="1.1192413e-05" iyz="-1.4400107e-11"
                izz="2.0712558e-05" />
      </inertial>
    </link>

    <joint name="base_link_to_${wheel_name}" type="continuous">
      <parent link="base_link"/>
      <child link="${wheel_name}"/>
      <origin xyz="${x} ${y} 0" rpy="0 1.57 0"/>
      <axis xyz="0 0 1"/>
    </joint>
  </xacro:macro>

  <xacro:oyku_wheel wheel_name="wheel_fl" x="${-lx}" y="${ly}" />
  <xacro:oyku_wheel wheel_name="wheel_fr" x="${lx}" y="${ly}" />
  <xacro:oyku_wheel wheel_name="wheel_rl" x="${-lx}" y="${-ly}" />
  <xacro:oyku_wheel wheel_name="wheel_rr" x="${lx}" y="${-ly}" />

  <link name="lidar">
    <visual>
      <origin xyz="0 0 -0.02" rpy="0 0 0"/>
      <geometry>
        <cylinder length="0.055" radius="0.035"/>
      </geometry>
      <material name="green"/>
    </visual>

    <collision>
      <origin xyz="0 0 0" rpy="0 0 0"/>
      <geometry>
        <cylinder length="0.055" radius="0.035"/>
      </geometry>
    </collision>

    <inertial>
      <mass value="0.114" />
      <origin xyz="0 0 0" />
      <inertia ixx="0.001" ixy="0.0" ixz="0.0"
               iyy="0.001" iyz="0.0"
               izz="0.001" />
    </inertial>
  </link>

  <joint name="scan_joint" type="fixed">
    <parent link="base_link"/>
    <child link="lidar"/>
    <origin xyz="0 0.05 0.1375" rpy="0 0 1.5708"/>
  </joint>

</robot>
